Workbook
Name base_monthly_revenue: 'Inputs'!$B$2
Name base_monthly_operating_expenses: 'Inputs'!$B$3
Name annual_revenue_growth: 'Inputs'!$B$4
Name annual_expense_growth: 'Inputs'!$B$5
Name vacancy_rate: 'Inputs'!$B$6
Name credit_loss_rate: 'Inputs'!$B$7
Name monthly_reserves: 'Inputs'!$B$8
Name month_1_gross_potential_revenue: 'Monthly'!$B$2
Name month_1_vacancy_loss: 'Monthly'!$C$2
Name month_1_credit_loss: 'Monthly'!$D$2
Name month_1_effective_gross_income: 'Monthly'!$E$2
Name month_1_operating_expenses: 'Monthly'!$F$2
Name month_1_reserves: 'Monthly'!$G$2
Name month_1_noi: 'Monthly'!$H$2
Name month_1_cash_flow: 'Monthly'!$I$2
Name month_2_gross_potential_revenue: 'Monthly'!$B$3
Name month_2_vacancy_loss: 'Monthly'!$C$3
Name month_2_credit_loss: 'Monthly'!$D$3
Name month_2_effective_gross_income: 'Monthly'!$E$3
Name month_2_operating_expenses: 'Monthly'!$F$3
Name month_2_reserves: 'Monthly'!$G$3
Name month_2_noi: 'Monthly'!$H$3
Name month_2_cash_flow: 'Monthly'!$I$3
Name month_3_gross_potential_revenue: 'Monthly'!$B$4
Name month_3_vacancy_loss: 'Monthly'!$C$4
Name month_3_credit_loss: 'Monthly'!$D$4
Name month_3_effective_gross_income: 'Monthly'!$E$4
Name month_3_operating_expenses: 'Monthly'!$F$4
Name month_3_reserves: 'Monthly'!$G$4
Name month_3_noi: 'Monthly'!$H$4
Name month_3_cash_flow: 'Monthly'!$I$4
Name month_4_gross_potential_revenue: 'Monthly'!$B$5
Name month_4_vacancy_loss: 'Monthly'!$C$5
Name month_4_credit_loss: 'Monthly'!$D$5
Name month_4_effective_gross_income: 'Monthly'!$E$5
Name month_4_operating_expenses: 'Monthly'!$F$5
Name month_4_reserves: 'Monthly'!$G$5
Name month_4_noi: 'Monthly'!$H$5
Name month_4_cash_flow: 'Monthly'!$I$5
Name month_5_gross_potential_revenue: 'Monthly'!$B$6
Name month_5_vacancy_loss: 'Monthly'!$C$6
Name month_5_credit_loss: 'Monthly'!$D$6
Name month_5_effective_gross_income: 'Monthly'!$E$6
Name month_5_operating_expenses: 'Monthly'!$F$6
Name month_5_reserves: 'Monthly'!$G$6
Name month_5_noi: 'Monthly'!$H$6
Name month_5_cash_flow: 'Monthly'!$I$6
Name month_6_gross_potential_revenue: 'Monthly'!$B$7
Name month_6_vacancy_loss: 'Monthly'!$C$7
Name month_6_credit_loss: 'Monthly'!$D$7
Name month_6_effective_gross_income: 'Monthly'!$E$7
Name month_6_operating_expenses: 'Monthly'!$F$7
Name month_6_reserves: 'Monthly'!$G$7
Name month_6_noi: 'Monthly'!$H$7
Name month_6_cash_flow: 'Monthly'!$I$7
Name month_7_gross_potential_revenue: 'Monthly'!$B$8
Name month_7_vacancy_loss: 'Monthly'!$C$8
Name month_7_credit_loss: 'Monthly'!$D$8
Name month_7_effective_gross_income: 'Monthly'!$E$8
Name month_7_operating_expenses: 'Monthly'!$F$8

Sheet Inputs
A1: Stored fact key | B1: Value | C1: Unit
A2: base_monthly_revenue | C2: USD/month
A3: base_monthly_operating_expenses | C3: USD/month
A4: annual_revenue_growth | C4: ratio
A5: annual_expense_growth | C5: ratio
A6: vacancy_rate | C6: ratio
A7: credit_loss_rate | C7: ratio
A8: monthly_reserves | C8: USD/month

Sheet Monthly
A1: Period | B1: gross_potential_revenue | C1: vacancy_loss | D1: credit_loss | E1: effective_gross_income | F1: operating_expenses | G1: reserves | H1: noi | I1: cash_flow
A2: Month 1 | B2: =base_monthly_revenue*(1+annual_revenue_growth)^0 | C2: =B2*vacancy_rate | D2: =(B2-C2)*credit_loss_rate | E2: =B2-C2-D2 | F2: =base_monthly_operating_expenses*(1+annual_expense_growth)^0 | G2: =monthly_reserves | H2: =E2-F2 | I2: =H2-G2
A3: Month 2 | B3: =base_monthly_revenue*(1+annual_revenue_growth)^0 | C3: =B3*vacancy_rate | D3: =(B3-C3)*credit_loss_rate | E3: =B3-C3-D3 | F3: =base_monthly_operating_expenses*(1+annual_expense_growth)^0 | G3: =monthly_reserves | H3: =E3-F3 | I3: =H3-G3
A4: Month 3 | B4: =base_monthly_revenue*(1+annual_revenue_growth)^0 | C4: =B4*vacancy_rate | D4: =(B4-C4)*credit_loss_rate | E4: =B4-C4-D4 | F4: =base_monthly_operating_expenses*(1+annual_expense_growth)^0 | G4: =monthly_reserves | H4: =E4-F4 | I4: =H4-G4
A5: Month 4 | B5: =base_monthly_revenue*(1+annual_revenue_growth)^0 | C5: =B5*vacancy_rate | D5: =(B5-C5)*credit_loss_rate | E5: =B5-C5-D5 | F5: =base_monthly_operating_expenses*(1+annual_expense_growth)^0 | G5: =monthly_reserves | H5: =E5-F5 | I5: =H5-G5
A6: Month 5 | B6: =base_monthly_revenue*(1+annual_revenue_growth)^0 | C6: =B6*vacancy_rate | D6: =(B6-C6)*credit_loss_rate | E6: =B6-C6-D6 | F6: =base_monthly_operating_expenses*(1+annual_expense_growth)^0 | G6: =monthly_reserves | H6: =E6-F6 | I6: =H6-G6
A7: Month 6 | B7: =base_monthly_revenue*(1+annual_revenue_growth)^0 | C7: =B7*vacancy_rate | D7: =(B7-C7)*credit_loss_rate | E7: =B7-C7-D7 | F7: =base_monthly_operating_expenses*(1+annual_expense_growth)^0 | G7: =monthly_reserves | H7: =E7-F7 | I7: =H7-G7
A8: Month 7 | B8: =base_monthly_revenue*(1+annual_revenue_growth)^0 | C8: =B8*vacancy_rate | D8: =(B8-C8)*credit_loss_rate | E8: =B8-C8-D8 | F8: =base_monthly_operating_expenses*(1+annual_expense_growth)^0 | G8: =monthly_reserves | H8: =E8-F8 | I8: =H8-G8
A9: Month 8 | B9: =base_monthly_revenue*(1+annual_revenue_growth)^0 | C9: =B9*vacancy_rate | D9: =(B9-C9)*credit_loss_rate | E9: =B9-C9-D9 | F9: =base_monthly_operating_expenses*(1+annual_expense_growth)^0 | G9: =monthly_reserves | H9: =E9-F9 | I9: =H9-G9
A10: Month 9 | B10: =base_monthly_revenue*(1+annual_revenue_growth)^0 | C10: =B10*vacancy_rate | D10: =(B10-C10)*credit_loss_rate | E10: =B10-C10-D10 | F10: =base_monthly_operating_expenses*(1+annual_expense_growth)^0 | G10: =monthly_reserves | H10: =E10-F10 | I10: =H10-G10
A11: Month 10 | B11: =base_monthly_revenue*(1+annual_revenue_growth)^0 | C11: =B11*vacancy_rate | D11: =(B11-C11)*credit_loss_rate | E11: =B11-C11-D11 | F11: =base_monthly_operating_expenses*(1+annual_expense_growth)^0 | G11: =monthly_reserves | H11: =E11-F11 | I11: =H11-G11
A12: Month 11 | B12: =base_monthly_revenue*(1+annual_revenue_growth)^0 | C12: =B12*vacancy_rate | D12: =(B12-C12)*credit_loss_rate | E12: =B12-C12-D12 | F12: =base_monthly_operating_expenses*(1+annual_expense_growth)^0 | G12: =monthly_reserves | H12: =E12-F12 | I12: =H12-G12
A13: Month 12 | B13: =base_monthly_revenue*(1+annual_revenue_growth)^0 | C13: =B13*vacancy_rate | D13: =(B13-C13)*credit_loss_rate | E13: =B13-C13-D13 | F13: =base_monthly_operating_expenses*(1+annual_expense_growth)^0 | G13: =monthly_reserves | H13: =E13-F13 | I13: =H13-G13
A14: Month 13 | B14: =base_monthly_revenue*(1+annual_revenue_growth)^1 | C14: =B14*vacancy_rate | D14: =(B14-C14)*credit_loss_rate | E14: =B14-C14-D14 | F14: =base_monthly_operating_expenses*(1+annual_expense_growth)^1 | G14: =monthly_reserves | H14: =E14-F14 | I14: =H14-G14
A15: Month 14 | B15: =base_monthly_revenue*(1+annual_revenue_growth)^1 | C15: =B15*vacancy_rate | D15: =(B15-C15)*credit_loss_rate | E15: =B15-C15-D15 | F15: =base_monthly_operating_expenses*(1+annual_expense_growth)^1 | G15: =monthly_reserves | H15: =E15-F15 | I15: =H15-G15
A16: Month 15 | B16: =base_monthly_revenue*(1+annual_revenue_growth)^1 | C16: =B16*vacancy_rate | D16: =(B16-C16)*credit_loss_rate | E16: =B16-C16-D16 | F16: =base_monthly_operating_expenses*(1+annual_expense_growth)^1 | G16: =monthly_reserves | H16: =E16-F16 | I16: =H16-G16
A17: Month 16 | B17: =base_monthly_revenue*(1+annual_revenue_growth)^1 | C17: =B17*vacancy_rate | D17: =(B17-C17)*credit_loss_rate | E17: =B17-C17-D17 | F17: =base_monthly_operating_expenses*(1+annual_expense_growth)^1 | G17: =monthly_reserves | H17: =E17-F17 | I17: =H17-G17
A18: Month 17 | B18: =base_monthly_revenue*(1+annual_revenue_growth)^1 | C18: =B18*vacancy_rate | D18: =(B18-C18)*credit_loss_rate | E18: =B18-C18-D18 | F18: =base_monthly_operating_expenses*(1+annual_expense_growth)^1 | G18: =monthly_reserves | H18: =E18-F18 | I18: =H18-G18
A19: Month 18 | B19: =base_monthly_revenue*(1+annual_revenue_growth)^1 | C19: =B19*vacancy_rate | D19: =(B19-C19)*credit_loss_rate | E19: =B19-C19-D19 | F19: =base_monthly_operating_expenses*(1+annual_expense_growth)^1 | G19: =monthly_reserves | H19: =E19-F19 | I19: =H19-G19
A20: Month 19 | B20: =base_monthly_revenue*(1+annual_revenue_growth)^1 | C20: =B20*vacancy_rate | D20: =(B20-C20)*credit_loss_rate | E20: =B20-C20-D20 | F20: =base_monthly_operating_expenses*(1+annual_expense_growth)^1 | G20: =monthly_reserves | H20: =E20-F20 | I20: =H20-G20
A21: Month 20 | B21: =base_monthly_revenue*(1+annual_revenue_growth)^1 | C21: =B21*vacancy_rate | D21: =(B21-C21)*credit_loss_rate | E21: =B21-C21-D21 | F21: =base_monthly_operating_expenses*(1+annual_expense_growth)^1 | G21: =monthly_reserves | H21: =E21-F21 | I21: =H21-G21
A22: Month 21 | B22: =base_monthly_revenue*(1+annual_revenue_growth)^1 | C22: =B22*vacancy_rate | D22: =(B22-C22)*credit_loss_rate | E22: =B22-C22-D22 | F22: =base_monthly_operating_expenses*(1+annual_expense_growth)^1 | G22: =monthly_reserves | H22: =E22-F22 | I22: =H22-G22
A23: Month 22 | B23: =base_monthly_revenue*(1+annual_revenue_growth)^1 | C23: =B23*vacancy_rate | D23: =(B23-C23)*credit_loss_rate | E23: =B23-C23-D23 | F23: =base_monthly_operating_expenses*(1+annual_expense_growth)^1 | G23: =monthly_reserves | H23: =E23-F23 | I23: =H23-G23
A24: Month 23 | B24: =base_monthly_revenue*(1+annual_revenue_growth)^1 | C24: =B24*vacancy_rate | D24: =(B24-C24)*credit_loss_rate | E24: =B24-C24-D24 | F24: =base_monthly_operating_expenses*(1+annual_expense_growth)^1 | G24: =monthly_reserves | H24: =E24-F24 | I24: =H24-G24
A25: Month 24 | B25: =base_monthly_revenue*(1+annual_revenue_growth)^1 | C25: =B25*vacancy_rate | D25: =(B25-C25)*credit_loss_rate | E25: =B25-C25-D25 | F25: =base_monthly_operating_expenses*(1+annual_expense_growth)^1 | G25: =monthly_reserves | H25: =E25-F25 | I25: =H25-G25
A26: Month 25 | B26: =base_monthly_revenue*(1+annual_revenue_growth)^2 | C26: =B26*vacancy_rate | D26: =(B26-C26)*credit_loss_rate | E26: =B26-C26-D26 | F26: =base_monthly_operating_expenses*(1+annual_expense_growth)^2 | G26: =monthly_reserves | H26: =E26-F26 | I26: =H26-G26
A27: Month 26 | B27: =base_monthly_revenue*(1+annual_revenue_growth)^2 | C27: =B27*vacancy_rate | D27: =(B27-C27)*credit_loss_rate | E27: =B27-C27-D27 | F27: =base_monthly_operating_expenses*(1+annual_expense_growth)^2 | G27: =monthly_reserves | H27: =E27-F27 | I27: =H27-G27
A28: Month 27 | B28: =base_monthly_revenue*(1+annual_revenue_growth)^2 | C28: =B28*vacancy_rate | D28: =(B28-C28)*credit_loss_rate | E28: =B28-C28-D28 | F28: =base_monthly_operating_expenses*(1+annual_expense_growth)^2 | G28: =monthly_reserves | H28: =E28-F28 | I28: =H28-G28
A29: Month 28 | B29: =base_monthly_revenue*(1+annual_revenue_growth)^2 | C29: =B29*vacancy_rate | D29: =(B29-C29)*credit_loss_rate | E29: =B29-C29-D29 | F29: =base_monthly_operating_expenses*(1+annual_expense_growth)^2 | G29: =monthly_reserves | H29: =E29-F29 | I29: =H29-G29
A30: Month 29 | B30: =base_monthly_revenue*(1+annual_revenue_growth)^2 | C30: =B30*vacancy_rate | D30: =(B30-C30)*credit_loss_rate | E30: =B30-C30-D30 | F30: =base_monthly_operating_expenses*(1+annual_expense_growth)^2 | G30: =monthly_reserves | H30: =E30-F30 | I30: =H30-G30
A31: Month 30 | B31: =base_monthly_revenue*(1+annual_revenue_growth)^2 | C31: =B31*vacancy_rate | D31: =(B31-C31)*credit_loss_rate | E31: =B31-C31-D31 | F31: =base_monthly_operating_expenses*(1+annual_expense_growth)^2 | G31: =monthly_reserves | H31: =E31-F31 | I31: =H31-G31
A32: Month 31 | B32: =base_monthly_revenue*(1+annual_revenue_growth)^2 | C32: =B32*vacancy_rate | D32: =(B32-C32)*credit_loss_rate | E32: =B32-C32-D32 | F32: =base_monthly_operating_expenses*(1+annual_expense_growth)^2 | G32: =monthly_reserves | H32: =E32-F32 | I32: =H32-G32
A33: Month 32 | B33: =base_monthly_revenue*(1+annual_revenue_growth)^2 | C33: =B33*vacancy_rate | D33: =(B33-C33)*credit_loss_rate | E33: =B33-C33-D33 | F33: =base_monthly_operating_expenses*(1+annual_expense_growth)^2 | G33: =monthly_reserves | H33: =E33-F33 | I33: =H33-G33
A34: Month 33 | B34: =base_monthly_revenue*(1+annual_revenue_growth)^2 | C34: =B34*vacancy_rate | D34: =(B34-C34)*credit_loss_rate | E34: =B34-C34-D34 | F34: =base_monthly_operating_expenses*(1+annual_expense_growth)^2 | G34: =monthly_reserves | H34: =E34-F34 | I34: =H34-G34
A35: Month 34 | B35: =base_monthly_revenue*(1+annual_revenue_growth)^2 | C35: =B35*vacancy_rate | D35: =(B35-C35)*credit_loss_rate | E35: =B35-C35-D35 | F35: =base_monthly_operating_expenses*(1+annual_expense_growth)^2 | G35: =monthly_reserves | H35: =E35-F35 | I35: =H35-G35
A36: Month 35 | B36: =base_monthly_revenue*(1+annual_revenue_growth)^2 | C36: =B36*vacancy_rate | D36: =(B36-C36)*credit_loss_rate | E36: =B36-C36-D36 | F36: =base_monthly_operating_expenses*(1+annual_expense_growth)^2 | G36: =monthly_reserves | H36: =E36-F36 | I36: =H36-G36
A37: Month 36 | B37: =base_monthly_revenue*(1+annual_revenue_growth)^2 | C37: =B37*vacancy_rate | D37: =(B37-C37)*credit_loss_rate | E37: =B37-C37-D37 | F37: =base_monthly_operating_expenses*(1+annual_expense_growth)^2 | G37: =monthly_reserves | H37: =E37-F37 | I37: =H37-G37
A38: Month 37 | B38: =base_monthly_revenue*(1+annual_revenue_growth)^3 | C38: =B38*vacancy_rate | D38: =(B38-C38)*credit_loss_rate | E38: =B38-C38-D38 | F38: =base_monthly_operating_expenses*(1+annual_expense_growth)^3 | G38: =monthly_reserves | H38: =E38-F38 | I38: =H38-G38
A39: Month 38 | B39: =base_monthly_revenue*(1+annual_revenue_growth)^3 | C39: =B39*vacancy_rate | D39: =(B39-C39)*credit_loss_rate | E39: =B39-C39-D39 | F39: =base_monthly_operating_expenses*(1+annual_expense_growth)^3 | G39: =monthly_reserves | H39: =E39-F39 | I39: =H39-G39
A40: Month 39 | B40: =base_monthly_revenue*(1+annual_revenue_growth)^3 | C40: =B40*vacancy_rate | D40: =(B40-C40)*credit_loss_rate | E40: =B40-C40-D40 | F40: =base_monthly_operating_expenses*(1+annual_expense_growth)^3 | G40: =monthly_reserves | H40: =E40-F40 | I40: =H40-G40
...

Sheet Annual
A1: Metric | C1: Year 1 | D1: Year 2 | E1: Year 3 | F1: Year 4 | G1: Year 5
A2: gross_potential_revenue | C2: =SUM(Monthly!B2:B13) | D2: =SUM(Monthly!B14:B25) | E2: =SUM(Monthly!B26:B37) | F2: =SUM(Monthly!B38:B49) | G2: =SUM(Monthly!B50:B61)
A3: effective_gross_income | C3: =SUM(Monthly!E2:E13) | D3: =SUM(Monthly!E14:E25) | E3: =SUM(Monthly!E26:E37) | F3: =SUM(Monthly!E38:E49) | G3: =SUM(Monthly!E50:E61)
A4: operating_expenses | C4: =SUM(Monthly!F2:F13) | D4: =SUM(Monthly!F14:F25) | E4: =SUM(Monthly!F26:F37) | F4: =SUM(Monthly!F38:F49) | G4: =SUM(Monthly!F50:F61)
A5: reserves | C5: =SUM(Monthly!G2:G13) | D5: =SUM(Monthly!G14:G25) | E5: =SUM(Monthly!G26:G37) | F5: =SUM(Monthly!G38:G49) | G5: =SUM(Monthly!G50:G61)
A6: noi | C6: =SUM(Monthly!H2:H13) | D6: =SUM(Monthly!H14:H25) | E6: =SUM(Monthly!H26:H37) | F6: =SUM(Monthly!H38:H49) | G6: =SUM(Monthly!H50:H61)
A7: cash_flow | C7: =SUM(Monthly!I2:I13) | D7: =SUM(Monthly!I14:I25) | E7: =SUM(Monthly!I26:I37) | F7: =SUM(Monthly!I38:I49) | G7: =SUM(Monthly!I50:I61)
